Workbook
Name Slicer_ai_intensity_level: #N/A
Name Slicer_ai_job_displacement_risk_level: #N/A
Name Slicer_ai_mentioned: #N/A
Name Slicer_AI_Period: #N/A
Name Slicer_company_group: #N/A
Name Slicer_industry: #N/A
Name Slicer_industry_ai_adoption_stage: #N/A
Name Slicer_job_title: #N/A
Name Slicer_posting_year: #N/A
Name Slicer_region: #N/A
Name Slicer_seniority_level: #N/A
Name Slicer_Skill_Type: #N/A

Sheet Raw Data 
A1: job_id | B1: posting_year | C1: country | D1: region | E1: company_name | F1: company_size | G1: industry | H1: job_title | I1: seniority_level | J1: ai_mentioned | K1: ai_keywords | L1: ai_intensity_score | M1: core_skills | N1: ai_skills | O1: salary_usd | P1: salary_change_vs_prev_year_percent | Q1: automation_risk_score | R1: reskilling_required | S1: ai_job_displacement_risk | T1: job_description_embedding_cluster | U1: industry_ai_adoption_stage | V1: Core_Business Analysis | W1: Core_Cloud Computing | X1: Core_Communication | Y1: Core_Data Analysis | Z1: Core_Project Management | AA1: Core_Python | AB1: Core_Research | AC1: Core_SQL | AD1: Core_Software Engineering | AE1: Core_Statistics | AF1: AI_LLMs | AG1: AI_MLOps | AH1: AI_NLP | AI1: AI_computer vision | AJ1: AI_deep learning | AK1: AI_generative AI | AL1: AI_machine learning | AM1: AI_reinforcement learning
A2: 87e6f4f5-16ce-4479-9ce4-6d3973e37e11 | B2: 2010 | C2: Indonesia | D2: Southeast Asia | E2: Future Analytics | F2: Enterprise | G2: Energy | H2: Product Manager | I2: Junior | J2: FALSE | L2: 0.01 | M2: Statistics, Communication, Business Analysis, Data Analysis, Project Management, Software Engineering | O2: 31284 | P2: -3.64 | Q2: 0.74 | R2: FALSE | S2: Low | T2: 15 | U2: Emerging | V2: TRUE | W2: FALSE | X2: TRUE | Y2: TRUE | Z2: TRUE | AA2: FALSE | AB2: FALSE | AC2: FALSE | AD2: TRUE | AE2: TRUE | AF2: FALSE | AG2: FALSE | AH2: FALSE | AI2: FALSE | AJ2: FALSE | AK2: FALSE | AL2: FALSE | AM2: FALSE
A3: c41a9305-8dd1-4716-8953-2be6a0f256d7 | B3: 2010 | C3: Italy | D3: Europe | E3: Prime Systems | F3: Small | G3: Agriculture | H3: Data Scientist | I3: Lead | J3: FALSE | L3: 0.19 | M3: Software Engineering, Communication, Research, Data Analysis, SQL | O3: 60960 | P3: 1.97 | Q3: 0.64 | R3: FALSE | S3: Low | T3: 8 | U3: Emerging | V3: FALSE | W3: FALSE | X3: TRUE | Y3: TRUE | Z3: FALSE | AA3: FALSE | AB3: TRUE | AC3: TRUE | AD3: TRUE | AE3: FALSE | AF3: FALSE | AG3: FALSE | AH3: FALSE | AI3: FALSE | AJ3: FALSE | AK3: FALSE | AL3: FALSE | AM3: FALSE
A4: af0a8661-6ad5-4679-9166-596671dabb4e | B4: 2010 | C4: Pakistan | D4: South Asia | E4: Global Solutions | F4: Small | G4: Manufacturing | H4: AI Researcher | I4: Lead | J4: FALSE | L4: 0.11 | M4: Python, Data Analysis, Cloud Computing, Communication, SQL | O4: 21791 | P4: -3.9 | Q4: 0.86 | R4: FALSE | S4: High | T4: 13 | U4: Emerging | V4: FALSE | W4: TRUE | X4: TRUE | Y4: TRUE | Z4: FALSE | AA4: TRUE | AB4: FALSE | AC4: TRUE | AD4: FALSE | AE4: FALSE | AF4: FALSE | AG4: FALSE | AH4: FALSE | AI4: FALSE | AJ4: FALSE | AK4: FALSE | AL4: FALSE | AM4: FALSE
A5: c14573ab-bda8-4a12-a65d-9a908b9345c1 | B5: 2010 | C5: Argentina | D5: South America | E5: Global Technologies | F5: Medium | G5: Government | H5: Policy Analyst | I5: Junior | J5: FALSE | L5: 0.08 | M5: Software Engineering, Research, Business Analysis, Data Analysis, SQL | O5: 31890 | P5: 0.02 | Q5: 0.78 | R5: FALSE | S5: Medium | T5: 17 | U5: Emerging | V5: TRUE | W5: FALSE | X5: FALSE | Y5: TRUE | Z5: FALSE | AA5: FALSE | AB5: TRUE | AC5: TRUE | AD5: TRUE | AE5: FALSE | AF5: FALSE | AG5: FALSE | AH5: FALSE | AI5: FALSE | AJ5: FALSE | AK5: FALSE | AL5: FALSE | AM5: FALSE
A6: e81fff60-4d14-4bb3-b4d2-98375f1333ef | B6: 2010 | C6: Bangladesh | D6: South Asia | E6: NextGen Analytics | F6: Small | G6: Education | H6: AI Researcher | I6: Lead | J6: FALSE | L6: 0.02 | M6: Cloud Computing, Business Analysis, Software Engineering, Communication, Statistics | O6: 22997 | P6: -0.21 | Q6: 0.67 | R6: FALSE | S6: Medium | T6: 9 | U6: Emerging | V6: TRUE | W6: TRUE | X6: TRUE | Y6: FALSE | Z6: FALSE | AA6: FALSE | AB6: FALSE | AC6: FALSE | AD6: TRUE | AE6: TRUE | AF6: FALSE | AG6: FALSE | AH6: FALSE | AI6: FALSE | AJ6: FALSE | AK6: FALSE | AL6: FALSE | AM6: FALSE
A7: f7a45b96-b8a4-4ece-8afa-937a6995ab0c | B7: 2010 | C7: Netherlands | D7: Europe | E7: NextGen Analytics | F7: Enterprise | G7: Education | H7: Policy Analyst | I7: Mid | J7: FALSE | L7: 0.16 | M7: Data Analysis, SQL, Statistics, Python, Business Analysis, Project Management | O7: 65776 | P7: 4.29 | Q7: 0.69 | R7: FALSE | S7: Low | T7: 2 | U7: Emerging | V7: TRUE | W7: FALSE | X7: FALSE | Y7: TRUE | Z7: TRUE | AA7: TRUE | AB7: FALSE | AC7: TRUE | AD7: FALSE | AE7: TRUE | AF7: FALSE | AG7: FALSE | AH7: FALSE | AI7: FALSE | AJ7: FALSE | AK7: FALSE | AL7: FALSE | AM7: FALSE
A8: aa7e6587-7a35-4c1c-a895-e8c5d6fd938a | B8: 2010 | C8: Sri Lanka | D8: South Asia | E8: NextGen Analytics | F8: Large | G8: Manufacturing | H8: ML Engineer | I8: Junior | J8: FALSE | L8: 0.02 | M8: Cloud Computing, Communication, Software Engineering, SQL, Python | O8: 22406 | P8: 4.05 | Q8: 0.89 | R8: FALSE | S8: Low | T8: 13 | U8: Emerging | V8: FALSE | W8: TRUE | X8: TRUE | Y8: FALSE | Z8: FALSE | AA8: TRUE | AB8: FALSE | AC8: TRUE | AD8: TRUE | AE8: FALSE | AF8: FALSE | AG8: FALSE | AH8: FALSE | AI8: FALSE | AJ8: FALSE | AK8: FALSE | AL8: FALSE | AM8: FALSE
A9: 9fc686af-ef4a-4cd5-ad8b-707ccf244cdf | B9: 2010 | C9: Argentina | D9: South America | E9: Global Analytics | F9: Startup | G9: Tech | H9: AI Researcher | I9: Mid | J9: FALSE | L9: 0.09 | M9: Business Analysis, Statistics, Cloud Computing, Communication | O9: 33771 | P9: -3.5 | Q9: 0.88 | R9: FALSE | S9: Low | T9: 18 | U9: Emerging | V9: TRUE | W9: TRUE | X9: TRUE | Y9: FALSE | Z9: FALSE | AA9: FALSE | AB9: FALSE | AC9: FALSE | AD9: FALSE | AE9: TRUE | AF9: FALSE | AG9: FALSE | AH9: FALSE | AI9: FALSE | AJ9: FALSE | AK9: FALSE | AL9: FALSE | AM9: FALSE
A10: 96d96af4-e6ec-4b53-aeaa-25001ab1f9a7 | B10: 2010 | C10: Morocco | D10: Africa | E10: Global Systems | F10: Small | G10: Agriculture | H10: Software Engineer | I10: Executive | J10: FALSE | L10: 0.14 | M10: Python, SQL, Business Analysis | O10: 19577 | P10: -1.25 | Q10: 0.79 | R10: FALSE | S10: Medium | T10: 12 | U10: Emerging | V10: TRUE | W10: FALSE | X10: FALSE | Y10: FALSE | Z10: FALSE | AA10: TRUE | AB10: FALSE | AC10: TRUE | AD10: FALSE | AE10: FALSE | AF10: FALSE | AG10: FALSE | AH10: FALSE | AI10: FALSE | AJ10: FALSE | AK10: FALSE | AL10: FALSE | AM10: FALSE
A11: b290f526-b029-423d-a2ff-2d0619490a99 | B11: 2010 | C11: United Kingdom | D11: Europe | E11: Future Solutions | F11: Enterprise | G11: Healthcare | H11: Data Scientist | I11: Lead | J11: FALSE | L11: 0.17 | M11: Research, Business Analysis, Communication, Software Engineering | O11: 66649 | P11: -4.25 | Q11: 0.75 | R11: FALSE | S11: Low | T11: 2 | U11: Emerging | V11: TRUE | W11: FALSE | X11: TRUE | Y11: FALSE | Z11: FALSE | AA11: FALSE | AB11: TRUE | AC11: FALSE | AD11: TRUE | AE11: FALSE | AF11: FALSE | AG11: FALSE | AH11: FALSE | AI11: FALSE | AJ11: FALSE | AK11: FALSE | AL11: FALSE | AM11: FALSE
A12: d70a7945-a010-41af-9c2e-f0ea6b954937 | B12: 2010 | C12: Mexico | D12: North America | E12: NextGen Analytics | F12: Startup | G12: Agriculture | H12: Research Scientist | I12: Mid | J12: FALSE | L12: 0.08 | M12: Research, Business Analysis, Statistics, Cloud Computing, Data Analysis | O12: 63813 | P12: 3.04 | Q12: 0.72 | R12: FALSE | S12: High | T12: 12 | U12: Emerging | V12: TRUE | W12: TRUE | X12: FALSE | Y12: TRUE | Z12: FALSE | AA12: FALSE | AB12: TRUE | AC12: FALSE | AD12: FALSE | AE12: TRUE | AF12: FALSE | AG12: FALSE | AH12: FALSE | AI12: FALSE | AJ12: FALSE | AK12: FALSE | AL12: FALSE | AM12: FALSE
A13: 87735b8c-0174-4f63-bee3-4a465c845e0e | B13: 2010 | C13: India | D13: South Asia | E13: Future Analytics | F13: Large | G13: Education | H13: Research Scientist | I13: Mid | J13: FALSE | L13: 0.07 | M13: Data Analysis, Software Engineering, Business Analysis, SQL, Project Management | O13: 20676 | P13: -2.4 | Q13: 0.76 | R13: FALSE | S13: High | T13: 11 | U13: Emerging | V13: TRUE | W13: FALSE | X13: FALSE | Y13: TRUE | Z13: TRUE | AA13: FALSE | AB13: FALSE | AC13: TRUE | AD13: TRUE | AE13: FALSE | AF13: FALSE | AG13: FALSE | AH13: FALSE | AI13: FALSE | AJ13: FALSE | AK13: FALSE | AL13: FALSE | AM13: FALSE
A14: d72386bf-805e-4357-9b1b-ebef4ccc4b01 | B14: 2010 | C14: Vietnam | D14: Southeast Asia | E14: NextGen Systems | F14: Enterprise | G14: Government | H14: Policy Analyst | I14: Executive | J14: FALSE | L14: 0.07 | M14: Project Management, Python, Software Engineering, Communication | O14: 29851 | P14: 3.74 | Q14: 0.69 | R14: FALSE | S14: High | T14: 16 | U14: Emerging | V14: FALSE | W14: FALSE | X14: TRUE | Y14: FALSE | Z14: TRUE | AA14: TRUE | AB14: FALSE | AC14: FALSE | AD14: TRUE | AE14: FALSE | AF14: FALSE | AG14: FALSE | AH14: FALSE | AI14: FALSE | AJ14: FALSE | AK14: FALSE | AL14: FALSE | AM14: FALSE
A15: 0ee5f304-67d0-457f-af2e-236ae874cd7e | B15: 2010 | C15: China | D15: East Asia | E15: Prime Solutions | F15: Startup | G15: Energy | H15: Software Engineer | I15: Junior | J15: TRUE | K15: computer vision, reinforcement learning, MLOps, deep learning | L15: 0.74 | M15: Python, Project Management, SQL, Business Analysis | N15: computer vision, reinforcement learning, MLOps, deep learning | O15: 87947 | P15: -1.39 | Q15: 0.3 | R15: TRUE | S15: Low | T15: 6 | U15: Emerging | V15: TRUE | W15: FALSE | X15: FALSE | Y15: FALSE | Z15: TRUE | AA15: TRUE | AB15: FALSE | AC15: TRUE | AD15: FALSE | AE15: FALSE | AF15: FALSE | AG15: TRUE | AH15: FALSE | AI15: TRUE | AJ15: TRUE | AK15: FALSE | AL15: FALSE | AM15: TRUE
A16: 0e14c8f1-6cfc-4c7d-96d6-9784d127888b | B16: 2010 | C16: Chile | D16: South America | E16: NextGen Technologies | F16: Enterprise | G16: Government | H16: Policy Analyst | I16: Mid | J16: FALSE | L16: 0.04 | M16: Business Analysis, Software Engineering, Research, SQL, Communication | O16: 30828 | P16: 0.95 | Q16: 0.62 | R16: FALSE | S16: Low | T16: 1 | U16: Emerging | V16: TRUE | W16: FALSE | X16: TRUE | Y16: FALSE | Z16: FALSE | AA16: FALSE | AB16: TRUE | AC16: TRUE | AD16: TRUE | AE16: FALSE | AF16: FALSE | AG16: FALSE | AH16: FALSE | AI16: FALSE | AJ16: FALSE | AK16: FALSE | AL16: FALSE | AM16: FALSE
A17: df8c6860-b83c-4456-91f5-225f9f52a46e | B17: 2010 | C17: Italy | D17: Europe | E17: Future Solutions | F17: Medium | G17: Government | H17: Research Scientist | I17: Intern | J17: FALSE | L17: 0.08 | M17: Data Analysis, Communication, Statistics | O17: 63343 | P17: -0.97 | Q17: 0.83 | R17: FALSE | S17: High | T17: 19 | U17: Emerging | V17: FALSE | W17: FALSE | X17: TRUE | Y17: TRUE | Z17: FALSE | AA17: FALSE | AB17: FALSE | AC17: FALSE | AD17: FALSE | AE17: TRUE | AF17: FALSE | AG17: FALSE | AH17: FALSE | AI17: FALSE | AJ17: FALSE | AK17: FALSE | AL17: FALSE | AM17: FALSE
A18: e9b1d916-45af-43de-b4d8-de60d0ec624a | B18: 2010 | C18: Poland | D18: Europe | E18: NextGen Technologies | F18: Large | G18: Finance | H18: Policy Analyst | I18: Intern | J18: TRUE | K18: machine learning, deep learning | L18: 0.92 | M18: Software Engineering, Cloud Computing, Data Analysis, Statistics, SQL, Business Analysis | N18: machine learning, deep learning | O18: 74564 | P18: -3.26 | Q18: 0.26 | R18: TRUE | S18: Medium | T18: 5 | U18: Emerging | V18: TRUE | W18: TRUE | X18: FALSE | Y18: TRUE | Z18: FALSE | AA18: FALSE | AB18: FALSE | AC18: TRUE | AD18: TRUE | AE18: TRUE | AF18: FALSE | AG18: FALSE | AH18: FALSE | AI18: FALSE | AJ18: TRUE | AK18: FALSE | AL18: TRUE | AM18: FALSE
A19: ace2f695-bd92-4719-ad0d-45d08ffaa638 | B19: 2010 | C19: Morocco | D19: Africa | E19: Global Analytics | F19: Enterprise | G19: Energy | H19: ML Engineer | I19: Executive | J19: FALSE | L19: 0.05 | M19: Data Analysis, SQL, Statistics, Business Analysis | O19: 19290 | P19: 4.51 | Q19: 0.85 | R19: FALSE | S19: Low | T19: 16 | U19: Emerging | V19: TRUE | W19: FALSE | X19: FALSE | Y19: TRUE | Z19: FALSE | AA19: FALSE | AB19: FALSE | AC19: TRUE | AD19: FALSE | AE19: TRUE | AF19: FALSE | AG19: FALSE | AH19: FALSE | AI19: FALSE | AJ19: FALSE | AK19: FALSE | AL19: FALSE | AM19: FALSE
A20: 67c1ff26-6e41-4ae1-8b3e-a05b1c48f810 | B20: 2010 | C20: UAE | D20: Middle East | E20: Global Analytics | F20: Small | G20: Healthcare | H20: Business Analyst | I20: Junior | J20: FALSE | L20: 0.08 | M20: Statistics, Data Analysis, Research | O20: 53320 | P20: 2.86 | Q20: 0.74 | R20: FALSE | S20: Medium | T20: 11 | U20: Emerging | V20: FALSE | W20: FALSE | X20: FALSE | Y20: TRUE | Z20: FALSE | AA20: FALSE | AB20: TRUE | AC20: FALSE | AD20: FALSE | AE20: TRUE | AF20: FALSE | AG20: FALSE | AH20: FALSE | AI20: FALSE | AJ20: FALSE | AK20: FALSE | AL20: FALSE | AM20: FALSE
A21: c326e290-7621-4132-ae37-6334fcaa63a7 | B21: 2010 | C21: Chile | D21: South America | E21: Global Solutions | F21: Medium | G21: Retail | H21: Systems Engineer | I21: Executive | J21: FALSE | L21: 0.1 | M21: Research, Data Analysis, Python | O21: 33051 | P21: -1.09 | Q21: 0.71 | R21: FALSE | S21: High | T21: 12 | U21: Emerging | V21: FALSE | W21: FALSE | X21: FALSE | Y21: TRUE | Z21: FALSE | AA21: TRUE | AB21: TRUE | AC21: FALSE | AD21: FALSE | AE21: FALSE | AF21: FALSE | AG21: FALSE | AH21: FALSE | AI21: FALSE | AJ21: FALSE | AK21: FALSE | AL21: FALSE | AM21: FALSE
A22: 4d58a197-61dc-40c0-b59d-e973c989e2fb | B22: 2010 | C22: Jordan | D22: Middle East | E22: Prime Technologies | F22: Small | G22: Government | H22: Research Scientist | I22: Senior | J22: FALSE | L22: 0.13 | M22: Statistics, Project Management, Research, Communication | O22: 51175 | P22: -4.64 | Q22: 0.82 | R22: FALSE | S22: High | T22: 0 | U22: Emerging | V22: FALSE | W22: FALSE | X22: TRUE | Y22: FALSE | Z22: TRUE | AA22: FALSE | AB22: TRUE | AC22: FALSE | AD22: FALSE | AE22: TRUE | AF22: FALSE | AG22: FALSE | AH22: FALSE | AI22: FALSE | AJ22: FALSE | AK22: FALSE | AL22: FALSE | AM22: FALSE
A23: 30bf1bc1-ab15-4b40-8df2-7a6aaace56f8 | B23: 2010 | C23: Bangladesh | D23: South Asia | E23: Future Solutions | F23: Medium | G23: Manufacturing | H23: Policy Analyst | I23: Senior | J23: FALSE | L23: 0.17 | M23: SQL, Data Analysis, Software Engineering, Project Management, Research | O23: 21195 | P23: 1.49 | Q23: 0.74 | R23: FALSE | S23: Low | T23: 17 | U23: Emerging | V23: FALSE | W23: FALSE | X23: FALSE | Y23: TRUE | Z23: TRUE | AA23: FALSE | AB23: TRUE | AC23: TRUE | AD23: TRUE | AE23: FALSE | AF23: FALSE | AG23: FALSE | AH23: FALSE | AI23: FALSE | AJ23: FALSE | AK23: FALSE | AL23: FALSE | AM23: FALSE
A24: f2e4f9c4-d248-4e30-85b6-dcd3b39995d0 | B24: 2010 | C24: Japan | D24: East Asia | E24: NextGen Analytics | F24: Startup | G24: Energy | H24: AI Researcher | I24: Lead | J24: TRUE | K24: NLP, MLOps | L24: 0.85 | M24: Python, Business Analysis, Data Analysis, Statistics, Project Management, SQL | N24: NLP, MLOps | O24: 79308 | P24: -1.65 | Q24: 0.39 | R24: TRUE | S24: Medium | T24: 10 | U24: Emerging | V24: TRUE | W24: FALSE | X24: FALSE | Y24: TRUE | Z24: TRUE | AA24: TRUE | AB24: FALSE | AC24: TRUE | AD24: FALSE | AE24: TRUE | AF24: FALSE | AG24: TRUE | AH24: TRUE | AI24: FALSE | AJ24: FALSE | AK24: FALSE | AL24: FALSE | AM24: FALSE
A25: b7360321-f197-4656-8cc7-91e2d46ee37a | B25: 2010 | C25: Mexico | D25: North America | E25: NextGen Systems | F25: Enterprise | G25: Agriculture | H25: ML Engineer | I25: Mid | J25: FALSE | L25: 0.04 | M25: Software Engineering, Project Management, SQL, Data Analysis, Statistics | O25: 67162 | P25: 3.99 | Q25: 0.61 | R25: FALSE | S25: High | T25: 9 | U25: Emerging | V25: FALSE | W25: FALSE | X25: FALSE | Y25: TRUE | Z25: TRUE | AA25: FALSE | AB25: FALSE | AC25: TRUE | AD25: TRUE | AE25: TRUE | AF25: FALSE | AG25: FALSE | AH25: FALSE | AI25: FALSE | AJ25: FALSE | AK25: FALSE | AL25: FALSE | AM25: FALSE
A26: d9375a32-1f84-46be-b37f-d1600e9ba3fc | B26: 2010 | C26: Malaysia | D26: Southeast Asia | E26: Future Analytics | F26: Medium | G26: Healthcare | H26: Operations Manager | I26: Executive | J26: FALSE | L26: 0.09 | M26: Project Management, Communication, Data Analysis, Research, Cloud Computing | O26: 26698 | P26: 1.37 | Q26: 0.77 | R26: FALSE | S26: Low | T26: 2 | U26: Emerging | V26: FALSE | W26: TRUE | X26: TRUE | Y26: TRUE | Z26: TRUE | AA26: FALSE | AB26: TRUE | AC26: FALSE | AD26: FALSE | AE26: FALSE | AF26: FALSE | AG26: FALSE | AH26: FALSE | AI26: FALSE | AJ26: FALSE | AK26: FALSE | AL26: FALSE | AM26: FALSE
A27: e4172c46-06c4-44d0-9d2b-34589f618847 | B27: 2010 | C27: Singapore | D27: Southeast Asia | E27: Prime Analytics | F27: Startup | G27: Government | H27: Data Scientist | I27: Senior | J27: FALSE | L27: 0.12 | M27: Software Engineering, Python, Project Management, SQL, Communication, Business Analysis | O27: 28203 | P27: 4.65 | Q27: 0.62 | R27: FALSE | S27: High | T27: 13 | U27: Emerging | V27: TRUE | W27: FALSE | X27: TRUE | Y27: FALSE | Z27: TRUE | AA27: TRUE | AB27: FALSE | AC27: TRUE | AD27: TRUE | AE27: FALSE | AF27: FALSE | AG27: FALSE | AH27: FALSE | AI27: FALSE | AJ27: FALSE | AK27: FALSE | AL27: FALSE | AM27: FALSE
A28: 4a83e29f-7eae-4f8b-9a0f-b8ebc1654a10 | B28: 2010 | C28: Jordan | D28: Middle East | E28: Global Analytics | F28: Medium | G28: Finance | H28: Data Scientist | I28: Mid | J28: FALSE | L28: 0.06 | M28: Research, Project Management, Business Analysis, Python, Cloud Computing, Software Engineering | O28: 46467 | P28: -3.21 | Q28: 0.74 | R28: FALSE | S28: Medium | T28: 19 | U28: Emerging | V28: TRUE | W28: TRUE | X28: FALSE | Y28: FALSE | Z28: TRUE | AA28: TRUE | AB28: TRUE | AC28: FALSE | AD28: TRUE | AE28: FALSE | AF28: FALSE | AG28: FALSE | AH28: FALSE | AI28: FALSE | AJ28: FALSE | AK28: FALSE | AL28: FALSE | AM28: FALSE
A29: 5864ae01-4908-442e-b70d-e2947eb5266e | B29: 2010 | C29: Mexico | D29: North America | E29: Global Systems | F29: Enterprise | G29: Government | H29: Product Manager | I29: Intern | J29: FALSE | L29: 0.1 | M29: Data Analysis, Communication, SQL, Project Management | O29: 69442 | P29: 3.75 | Q29: 0.83 | R29: FALSE | S29: Low | T29: 1 | U29: Emerging | V29: FALSE | W29: FALSE | X29: TRUE | Y29: TRUE | Z29: TRUE | AA29: FALSE | AB29: FALSE | AC29: TRUE | AD29: FALSE | AE29: FALSE | AF29: FALSE | AG29: FALSE | AH29: FALSE | AI29: FALSE | AJ29: FALSE | AK29: FALSE | AL29: FALSE | AM29: FALSE
A30: 0d23a73e-d9c2-417d-abba-db1e513b7d36 | B30: 2010 | C30: Australia | D30: Oceania | E30: Future Solutions | F30: Enterprise | G30: Government | H30: Operations Manager | I30: Executive | J30: FALSE | L30: 0.12 | M30: Cloud Computing, Python, Project Management, Business Analysis, Communication, Research | O30: 63731 | P30: -1.01 | Q30: 0.85 | R30: FALSE | S30: Medium | T30: 13 | U30: Emerging | V30: TRUE | W30: TRUE | X30: TRUE | Y30: FALSE | Z30: TRUE | AA30: TRUE | AB30: TRUE | AC30: FALSE | AD30: FALSE | AE30: FALSE | AF30: FALSE | AG30: FALSE | AH30: FALSE | AI30: FALSE | AJ30: FALSE | AK30: FALSE | AL30: FALSE | AM30: FALSE
A31: 0f11e2b3-70ef-454a-be99-c253a5f38982 | B31: 2010 | C31: Nepal | D31: South Asia | E31: Prime Technologies | F31: Startup | G31: Energy | H31: Systems Engineer | I31: Junior | J31: FALSE | L31: 0.03 | M31: Cloud Computing, Business Analysis, Software Engineering, Python, Data Analysis | O31: 18127 | P31: -2.89 | Q31: 0.73 | R31: FALSE | S31: Medium | T31: 5 | U31: Emerging | V31: TRUE | W31: TRUE | X31: FALSE | Y31: TRUE | Z31: FALSE | AA31: TRUE | AB31: FALSE | AC31: FALSE | AD31: TRUE | AE31: FALSE | AF31: FALSE | AG31: FALSE | AH31: FALSE | AI31: FALSE | AJ31: FALSE | AK31: FALSE | AL31: FALSE | AM31: FALSE
A32: 6ba8cf52-8995-41e4-bc80-b31400e95a02 | B32: 2010 | C32: UAE | D32: Middle East | E32: Global Solutions | F32: Enterprise | G32: Education | H32: ML Engineer | I32: Junior | J32: FALSE | L32: 0.05 | M32: SQL, Python, Research, Statistics, Business Analysis, Project Management | O32: 51548 | P32: 4.9 | Q32: 0.84 | R32: FALSE | S32: High | T32: 15 | U32: Emerging | V32: TRUE | W32: FALSE | X32: FALSE | Y32: FALSE | Z32: TRUE | AA32: TRUE | AB32: TRUE | AC32: TRUE | AD32: FALSE | AE32: TRUE | AF32: FALSE | AG32: FALSE | AH32: FALSE | AI32: FALSE | AJ32: FALSE | AK32: FALSE | AL32: FALSE | AM32: FALSE
A33: be913d77-70d9-463e-b8c3-a5546aa5c3fd | B33: 2010 | C33: Israel | D33: Middle East | E33: Global Analytics | F33: Enterprise | G33: Finance | H33: ML Engineer | I33: Intern | J33: FALSE | L33: 0.02 | M33: Cloud Computing, Python, Business Analysis, Software Engineering, Data Analysis | O33: 51928 | P33: -0.29 | Q33: 0.8 | R33: FALSE | S33: Low | T33: 14 | U33: Emerging | V33: TRUE | W33: TRUE | X33: FALSE | Y33: TRUE | Z33: FALSE | AA33: TRUE | AB33: FALSE | AC33: FALSE | AD33: TRUE | AE33: FALSE | AF33: FALSE | AG33: FALSE | AH33: FALSE | AI33: FALSE | AJ33: FALSE | AK33: FALSE | AL33: FALSE | AM33: FALSE
A34: 79aa7786-2b62-46d0-90fb-c7096eba6ff8 | B34: 2010 | C34: Argentina | D34: South America | E34: Future Systems | F34: Large | G34: Agriculture | H34: Business Analyst | I34: Lead | J34: FALSE | L34: 0.01 | M34: Python, Software Engineering, Business Analysis, Statistics, SQL | O34: 33399 | P34: 3.68 | Q34: 0.64 | R34: FALSE | S34: Medium | T34: 6 | U34: Emerging | V34: TRUE | W34: FALSE | X34: FALSE | Y34: FALSE | Z34: FALSE | AA34: TRUE | AB34: FALSE | AC34: TRUE | AD34: TRUE | AE34: TRUE | AF34: FALSE | AG34: FALSE | AH34: FALSE | AI34: FALSE | AJ34: FALSE | AK34: FALSE | AL34: FALSE | AM34: FALSE
A35: 29b4673a-47c5-4bff-b935-a0b0355de8cc | B35: 2010 | C35: Mexico | D35: North America | E35: NextGen Analytics | F35: Medium | G35: Tech | H35: ML Engineer | I35: Lead | J35: FALSE | L35: 0.01 | M35: Statistics, SQL, Data Analysis, Cloud Computing | O35: 78508 | P35: 0.63 | Q35: 0.86 | R35: FALSE | S35: Medium | T35: 18 | U35: Emerging | V35: FALSE | W35: TRUE | X35: FALSE | Y35: TRUE | Z35: FALSE | AA35: FALSE | AB35: FALSE | AC35: TRUE | AD35: FALSE | AE35: TRUE | AF35: FALSE | AG35: FALSE | AH35: FALSE | AI35: FALSE | AJ35: FALSE | AK35: FALSE | AL35: FALSE | AM35: FALSE
A36: 895e8453-0013-4525-8c09-7962fce852f3 | B36: 2010 | C36: Pakistan | D36: South Asia | E36: Prime Analytics | F36: Large | G36: Government | H36: Systems Engineer | I36: Junior | J36: FALSE | L36: 0.17 | M36: Python, Statistics, SQL, Communication, Data Analysis, Project Management | O36: 22122 | P36: -2.22 | Q36: 0.66 | R36: FALSE | S36: High | T36: 9 | U36: Emerging | V36: FALSE | W36: FALSE | X36: TRUE | Y36: TRUE | Z36: TRUE | AA36: TRUE | AB36: FALSE | AC36: TRUE | AD36: FALSE | AE36: TRUE | AF36: FALSE | AG36: FALSE | AH36: FALSE | AI36: FALSE | AJ36: FALSE | AK36: FALSE | AL36: FALSE | AM36: FALSE
... A39: 42e699e7-784d-46dc-ab26-06816675f5de | B39: 2010 | C39: Canada | D39: North America | E39: Prime Solutions | F39: Large | G39: Manufacturing | H39: Software Engineer | I39: Mid | J39: FALSE | L39: 0.11 | M39: Python, Cloud Computing, Communication, Software Engineering, Data Analysis, SQL | O39: 62849 | P39: -4.46 | Q39: 0.66 | R39: FALSE | S39: Medium | T39: 14 | U39: Emerging | V39: FALSE | W39: TRUE | X39: TRUE | Y39: TRUE | Z39: FALSE | AA39: TRUE | AB39: FALSE | AC39: TRUE | AD39: TRUE | AE39: FALSE | AF39: FALSE | AG39: FALSE | AH39: FALSE | AI39: FALSE | AJ39: FALSE | AK39: FALSE | AL39: FALSE | AM39: FALSE
A40: 8ebdd1b0-53f6-4656-b5f2-bd38402ed789 | B40: 2010 | C40: Nigeria | D40: Africa | E40: Global Analytics | F40: Small | G40: Government | H40: Software Engineer | I40: Executive | J40: TRUE | K40: reinforcement learning | L40: 0.53 | M40: Project Management, SQL, Business Analysis, Statistics | N40: reinforcement learning | O40: 27995 | P40: 0.8 | Q40: 0.27 | R40: TRUE | S40: Medium | T40: 0 | U40: Emerging | V40: TRUE | W40: FALSE | X40: FALSE | Y40: FALSE | Z40: TRUE | AA40: FALSE | AB40: FALSE | AC40: TRUE | AD40: FALSE | AE40: TRUE | AF40: FALSE | AG40: FALSE | AH40: FALSE | AI40: FALSE | AJ40: FALSE | AK40: FALSE | AL40: FALSE | AM40: TRUE
A41: da80282d-84fd-488d-bdbe-7ed357e95a4e | B41: 2010 | C41: Australia | D41: Oceania | E41: NextGen Analytics | F41: Medium | G41: Manufacturing | H41: AI Researcher | I41: Lead | J41: FALSE | L41: 0.13 | M41: Business Analysis, Cloud Computing, Project Management | O41: 65925 | P41: -0.26 | Q41: 0.86 | R41: FALSE | S41: Low | T41: 2 | U41: Emerging | V41: TRUE | W41: TRUE | X41: FALSE | Y41: FALSE | Z41: TRUE | AA41: FALSE | AB41: FALSE | AC41: FALSE | AD41: FALSE | AE41: FALSE | AF41: FALSE | AG41: FALSE | AH41: FALSE | AI41: FALSE | AJ41: FALSE | AK41: FALSE | AL41: FALSE | AM41: FALSE
A42: 546d60c7-84f0-4645-98ac-06b34831eab3 | B42: 2010 | C42: India | D42: South Asia | E42: Future Technologies | F42: Small | G42: Manufacturing | H42: Operations Manager | I42: Senior | J42: FALSE | L42: 0.13 | M42: Communication, Research, Software Engineering | O42: 17654 | P42: 4.5 | Q42: 0.84 | R42: FALSE | S42: High | T42: 1 | U42: Emerging | V42: FALSE | W42: FALSE | X42: TRUE | Y42: FALSE | Z42: FALSE | AA42: FALSE | AB42: TRUE | AC42: FALSE | AD42: TRUE | AE42: FALSE | AF42: FALSE | AG42: FALSE | AH42: FALSE | AI42: FALSE | AJ42: FALSE | AK42: FALSE | AL42: FALSE | AM42: FALSE
...

Sheet Fact_JobPosting
A1: Job_Key | B1: JobDisp_key | C1: AI Level_Key | D1: IndustryAi_Key | E1: SeniorityLevel_Key | F1: JobTitle_Key | G1: Industry_Key | H1: Company_Key | I1: Geo_Key | J1: Year_Key | K1: job_id | L1: posting_year | M1: Column1 | N1: ai_mentioned | O1: ai_intensity_score | P1: salary_usd | Q1: salary_change_vs_prev_year_percent | R1: ai_job_displacement_risk_score
A2: 1 | B2: 1 | C2: 1 | D2: 1 | E2: 1 | F2: 1 | G2: 3 | H2: 1 | I2: 1 | J2: 0 | K2: 87e6f4f5-16ce-4479-9ce4-6d3973e37e11 | L2: 2010 | M2: =IF(Fact_JobPosting[[#This Row],[ai_mentioned]]=1,"AI Jobs","Non AI Jobs") -> Non AI Jobs | N2: 0 | O2: 0.01 | P2: 31284 | Q2: -3.64 | R2: 0.74
A3: 2 | B3: 1 | C3: 1 | D3: 1 | E3: 1 | F3: 4 | G3: 5 | H3: 8 | I3: 4 | J3: 0 | K3: c14573ab-bda8-4a12-a65d-9a908b9345c1 | L3: 2010 | M3: =IF(Fact_JobPosting[[#This Row],[ai_mentioned]]=1,"AI Jobs","Non AI Jobs") -> Non AI Jobs | N3: 0 | O3: 0.08 | P3: 31890 | Q3: 0.02 | R3: 0.78
A4: 3 | B4: 1 | C4: 1 | D4: 1 | E4: 2 | F4: 3 | G4: 7 | H4: 6 | I4: 3 | J4: 0 | K4: af0a8661-6ad5-4679-9166-596671dabb4e | L4: 2010 | M4: =IF(Fact_JobPosting[[#This Row],[ai_mentioned]]=1,"AI Jobs","Non AI Jobs") -> Non AI Jobs | N4: 0 | O4: 0.11 | P4: 21791 | Q4: -3.9 | R4: 0.86
A5: 4 | B5: 2 | C5: 1 | D5: 1 | E5: 2 | F5: 2 | G5: 1 | H5: 15 | I5: 2 | J5: 0 | K5: c41a9305-8dd1-4716-8953-2be6a0f256d7 | L5: 2010 | M5: =IF(Fact_JobPosting[[#This Row],[ai_mentioned]]=1,"AI Jobs","Non AI Jobs") -> Non AI Jobs | N5: 0 | O5: 0.19 | P5: 60960 | Q5: 1.97 | R5: 0.64
A6: 5 | B6: 1 | C6: 1 | D6: 1 | E6: 3 | F6: 3 | G6: 9 | H6: 5 | I6: 4 | J6: 0 | K6: 9fc686af-ef4a-4cd5-ad8b-707ccf244cdf | L6: 2010 | M6: =IF(Fact_JobPosting[[#This Row],[ai_mentioned]]=1,"AI Jobs","Non AI Jobs") -> Non AI Jobs | N6: 0 | O6: 0.09 | P6: 33771 | Q6: -3.5 | R6: 0.88
A7: 6 | B7: 2 | C7: 1 | D7: 1 | E7: 2 | F7: 3 | G7: 2 | H7: 9 | I7: 5 | J7: 0 | K7: e81fff60-4d14-4bb3-b4d2-98375f1333ef | L7: 2010 | M7: =IF(Fact_JobPosting[[#This Row],[ai_mentioned]]=1,"AI Jobs","Non AI Jobs") -> Non AI Jobs | N7: 0 | O7: 0.02 | P7: 22997 | Q7: -0.21 | R7: 0.67
A8: 7 | B8: 2 | C8: 1 | D8: 1 | E8: 3 | F8: 4 | G8: 2 | H8: 9 | I8: 6 | J8: 0 | K8: f7a45b96-b8a4-4ece-8afa-937a6995ab0c | L8: 2010 | M8: =IF(Fact_JobPosting[[#This Row],[ai_mentioned]]=1,"AI Jobs","Non AI Jobs") -> Non AI Jobs | N8: 0 | O8: 0.16 | P8: 65776 | Q8: 4.29 | R8: 0.69
A9: 8 | B9: 1 | C9: 1 | D9: 1 | E9: 1 | F9: 5 | G9: 7 | H9: 9 | I9: 7 | J9: 0 | K9: aa7e6587-7a35-4c1c-a895-e8c5d6fd938a | L9: 2010 | M9: =IF(Fact_JobPosting[[#This Row],[ai_mentioned]]=1,"AI Jobs","Non AI Jobs") -> Non AI Jobs | N9: 0 | O9: 0.02 | P9: 22406 | Q9: 4.05 | R9: 0.89
A10: 9 | B10: 1 | C10: 1 | D10: 1 | E10: 4 | F10: 6 | G10: 1 | H10: 7 | I10: 8 | J10: 0 | K10: 96d96af4-e6ec-4b53-aeaa-25001ab1f9a7 | L10: 2010 | M10: =IF(Fact_JobPosting[[#This Row],[ai_mentioned]]=1,"AI Jobs","Non AI Jobs") -> Non AI Jobs | N10: 0 | O10: 0.14 | P10: 19577 | Q10: -1.25 | R10: 0.79
A11: 10 | B11: 1 | C11: 1 | D11: 1 | E11: 2 | F11: 2 | G11: 6 | H11: 2 | I11: 9 | J11: 0 | K11: b290f526-b029-423d-a2ff-2d0619490a99 | L11: 2010 | M11: =IF(Fact_JobPosting[[#This Row],[ai_mentioned]]=1,"AI Jobs","Non AI Jobs") -> Non AI Jobs | N11: 0 | O11: 0.17 | P11: 66649 | Q11: -4.25 | R11: 0.75
A12: 11 | B12: 1 | C12: 1 | D12: 1 | E12: 3 | F12: 7 | G12: 1 | H12: 9 | I12: 10 | J12: 0 | K12: d70a7945-a010-41af-9c2e-f0ea6b954937 | L12: 2010 | M12: =IF(Fact_JobPosting[[#This Row],[ai_mentioned]]=1,"AI Jobs","Non AI Jobs") -> Non AI Jobs | N12: 0 | O12: 0.08 | P12: 63813 | Q12: 3.04 | R12: 0.72
A13: 12 | B13: 1 | C13: 1 | D13: 1 | E13: 3 | F13: 7 | G13: 2 | H13: 1 | I13: 11 | J13: 0 | K13: 87735b8c-0174-4f63-bee3-4a465c845e0e | L13: 2010 | M13: =IF(Fact_JobPosting[[#This Row],[ai_mentioned]]=1,"AI Jobs","Non AI Jobs") -> Non AI Jobs | N13: 0 | O13: 0.07 | P13: 20676 | Q13: -2.4 | R13: 0.76
... A5001: 5000 | B5001: 3 | C5001: 3 | D5001: 2 | E5001: 3 | F5001: 5 | G5001: 8 | H5001: 12 | I5001: 3 | J5001: 15 | K5001: ff148884-e18a-4a5a-b899-241eebf32b99 | L5001: 2025 | M5001: =IF(Fact_JobPosting[[#This Row],[ai_mentioned]]=1,"AI Jobs","Non AI Jobs") -> AI Jobs | N5001: 1 | O5001: 0.53 | P5001: 37739 | Q5001: 8.25 | R5001: 0.38

Sheet Dim_Year
A1: Year_Key | B1: posting_year | C1: AI_Period
A2: 0 | B2: 2010 | C2: Pre-AI
A3: 1 | B3: 2011 | C3: Pre-AI
A4: 2 | B4: 2012 | C4: Pre-AI
A5: 3 | B5: 2013 | C5: Pre-AI
A6: 4 | B6: 2014 | C6: Pre-AI
A7: 5 | B7: 2015 | C7: Pre-AI
A8: 6 | B8: 2016 | C8: Early AI
A9: 7 | B9: 2017 | C9: Early AI
A10: 8 | B10: 2018 | C10: Early AI
A11: 9 | B11: 2019 | C11: Early AI
A12: 10 | B12: 2020 | C12: Early AI
A13: 11 | B13: 2021 | C13: Early AI
... A17: 15 | B17: 2025 | C17: Modern AI

Sheet Dim_Geography
A1: Geo_Key | B1: country | C1: region
A2: 1 | B2: Indonesia | C2: Southeast Asia
A3: 2 | B3: Italy | C3: Europe
A4: 3 | B4: Pakistan | C4: South Asia
A5: 4 | B5: Argentina | C5: South America
A6: 5 | B6: Bangladesh | C6: South Asia
A7: 6 | B7: Netherlands | C7: Europe
A8: 7 | B8: Sri Lanka | C8: South Asia
A9: 8 | B9: Morocco | C9: Africa
A10: 9 | B10: United Kingdom | C10: Europe
A11: 10 | B11: Mexico | C11: North America
A12: 11 | B12: India | C12: South Asia
A13: 12 | B13: Vietnam | C13: Southeast Asia
... A45: 44 | B45: Egypt | C45: Africa

Sheet Dim_Company
A1: Company_Key | B1: company_name | C1: company_group
A2: 1 | B2: Future Analytics | C2: Future
A3: 2 | B3: Future Solutions | C3: Future
A4: 3 | B4: Future Systems | C4: Future
A5: 4 | B5: Future Technologies | C5: Future
A6: 5 | B6: Global Analytics | C6: Global
A7: 6 | B7: Global Solutions | C7: Global
A8: 7 | B8: Global Systems | C8: Global
A9: 8 | B9: Global Technologies | C9: Global
A10: 9 | B10: NextGen Analytics | C10: NextGen
A11: 10 | B11: NextGen Solutions | C11: NextGen
A12: 11 | B12: NextGen Systems | C12: NextGen
A13: 12 | B13: NextGen Technologies | C13: NextGen
... A17: 16 | B17: Prime Technologies | C17: Prime

Sheet Dim_Industry
A1: Industry_Key | B1: industry
A2: 1 | B2: Agriculture
A3: 2 | B3: Education
A4: 3 | B4: Energy
A5: 4 | B5: Finance
A6: 5 | B6: Government
A7: 6 | B7: Healthcare
A8: 7 | B8: Manufacturing
A9: 8 | B9: Retail
A10: 9 | B10: Tech

Sheet Dim_IndustryAI
A1: IndustryAi_Key | B1: industry_ai_adoption_stage
A2: 1 | B2: Emerging
A3: 2 | B3: Growing
A4: 3 | B4: Mature

Sheet Dim_JobTitle
A1: JobTitle_Key | B1: job_title
A2: 1 | B2: Product Manager
A3: 2 | B3: Data Scientist
A4: 3 | B4: AI Researcher
A5: 4 | B5: Policy Analyst
A6: 5 | B6: ML Engineer
A7: 6 | B7: Software Engineer
A8: 7 | B8: Research Scientist
A9: 8 | B9: Business Analyst
A10: 9 | B10: Systems Engineer
A11: 10 | B11: Operations Manager

Sheet Dim_JobDisplacement
A1: JobDisp_key | B1: ai_job_displacement_risk_level
A2: 1 | B2: High Risk
A3: 2 | B3: Medium Risk
A4: 3 | B4: Low Risk

Sheet Dim_SeniorityLevel
A1: SeniorityLevel_Key | B1: seniority_level
A2: 1 | B2: Junior
A3: 2 | B3: Lead
A4: 3 | B4: Mid
A5: 4 | B5: Executive
A6: 5 | B6: Intern
A7: 6 | B7: Senior

Sheet Dim_Skill
A1: Skill_Key | B1: Skill_Name | C1: Skill_Type
A2: 1 | B2: Business Analysis | C2: Core
A3: 2 | B3: Cloud Computing | C3: Core
A4: 3 | B4: Communication | C4: Core
A5: 4 | B5: Data Analysis | C5: Core
A6: 5 | B6: Project Management | C6: Core
A7: 6 | B7: Python | C7: Core
A8: 7 | B8: Research | C8: Core
A9: 8 | B9: SQL | C9: Core
A10: 9 | B10: Software Engineering | C10: Core
A11: 10 | B11: Statistics | C11: Core
A12: 11 | B12: LLMs | C12: AI
A13: 12 | B13: MLOps | C13: AI
... A19: 18 | B19: reinforcement learning | C19: AI

Sheet Dim_AI Level
A1: AI Level_Key | B1: ai_intensity_level
A2: 1 | B2: Low
A3: 2 | B3: High
A4: 3 | B4: Medium

Sheet Bridge Skill_JobPosting
A1: Job_Key | B1: Skill_Key
A2: 1 | B2: 1
A3: 2 | B3: 1
A4: 1 | B4: 3
A5: 3 | B5: 3
A6: 4 | B6: 3
A7: 3 | B7: 2
A8: 1 | B8: 4
A9: 2 | B9: 4
A10: 3 | B10: 4
A11: 4 | B11: 4
A12: 1 | B12: 5
A13: 1 | B13: 9
... A26589: 5000 | B26589: 17

Sheet Pivots & Slicers
A1: Row Labels | B1: Distinct Count of job_id | D1: Row Labels | E1: Distinct Count of job_id
A2: AI Jobs | B2: 1623 | D2: Low Risk | E2: 1596
A3: Non AI Jobs | B3: 3377 | D3: Medium Risk | E3: 1112
A4: Grand Total | B4: 5000 | D4: High Risk | E4: 2292
D5: Grand Total | E5: 5000
A9: Row Labels | B9: Average of salary_usd | D9: Row Labels | E9: Average of salary_usd
A10: AI Jobs | B10: 83846.34 | D10: 0 | E10: 48264.079 | G10: 0 | H10: 48264.079 | J10: Row Labels | K10: Average of salary_usd | O10: Row Labels | P10: Average of salary_usd | R10: Row Labels | S10: Average of salary_usd | U10: Row Labels | V10: Average of salary_usd | X10: Row Labels | Y10: Average of salary_usd | AA10: Row Labels | AB10: Average of salary_usd
A11: Non AI Jobs | B11: 53123.575 | D11: 0.01 | E11: 52928.651 | G11: 0.01 | H11: 52928.651 | J11: Agriculture | K11: 61125.025 | O11: Intern | P11: 62313.945 | R11: Research Scientist | S11: 60502.438 | U11: Prime | V11: 62234.155 | X11: Africa | Y11: 25192.461 | AA11: Nigeria | AB11: 24579.54 | AD11: Nigeria | AE11: 24579.54 | AG11: Australia | AH11: 90815.922
D12: 0.02 | E12: 54085.736 | G12: 0.02 | H12: 54085.736 | J12: Retail | K12: 61822.22 | O12: Junior | P12: 63495.569 | R12: AI Researcher | S12: 61766.088 | U12: Global | V12: 62720.531 | X12: South Asia | Y12: 27888.041 | AA12: Egypt | AB12: 25031.931 | AD12: Egypt | AE12: 25031.931 | AG12: New Zealand | AH12: 92967.753
D13: 0.03 | E13: 54101.638 | G13: 0.03 | H13: 54101.638 | J13: Education | K13: 62098.826 | O13: Senior | P13: 65839.88 | R13: Policy Analyst | S13: 61935.685 | U13: NextGen | V13: 62739.074 | X13: Southeast Asia | Y13: 42078.743 | AA13: Morocco | AB13: 25118.612 | AD13: Morocco | AE13: 25118.612 | AG13: United States | AH13: 97374.498
D14: 0.04 | E14: 52400.554 | G14: 0.04 | H14: 52400.554 | J14: Healthcare | K14: 62502.043 | O14: Lead | P14: 62494.327 | R14: Systems Engineer | S14: 62466.634 | U14: Future | V14: 64643.614 | X14: South America | Y14: 49145.045 | AA14: South Africa | AB14: 25266.475 | AD14: South Africa | AE14: 25266.475 | AG14: Mexico | AH14: 100554.45
D15: 0.05 | E15: 52478.678 | G15: 0.05 | H15: 52478.678 | J15: Energy | K15: 62725.852 | O15: Executive | P15: 61408.993 | R15: Product Manager | S15: 62787.057 | X15: Middle East | Y15: 69679.214 | AA15: Kenya | AB15: 25412.182 | AD15: Kenya | AE15: 25412.182 | AG15: Canada | AH15: 101280.23
D16: 0.06 | E16: 52964.225 | G16: 0.06 | H16: 52964.225 | J16: Manufacturing | K16: 62882.091 | O16: Mid | P16: 62987.61 | R16: Business Analyst | S16: 63349.838 | X16: East Asia | Y16: 76910.589 | AA16: Ghana | AB16: 25732.129 | AD16: Ghana | AE16: 25732.129
D17: 0.07 | E17: 54668.69 | G17: 0.07 | H17: 54668.69 | J17: Government | K17: 63088.815 | R17: Software Engineer | S17: 63890.99 | X17: Europe | Y17: 82624.719 | AA17: Bangladesh | AB17: 27084.33 | AD17: Bangladesh | AE17: 27084.33
D18: 0.08 | E18: 53117.144 | G18: 0.08 | H18: 53117.144 | J18: Finance | K18: 65276.938 | R18: Operations Manager | S18: 64642.131 | X18: Oceania | Y18: 91839.647 | AA18: Sri Lanka | AB18: 27609.812 | AD18: Sri Lanka | AE18: 27609.812
D19: 0.09 | E19: 52727.924 | G19: 0.09 | H19: 52727.924 | J19: Tech | K19: 66262.012 | R19: Data Scientist | S19: 64735.481 | X19: North America | Y19: 99658.754 | AA19: Pakistan | AB19: 28073.4 | AD19: Pakistan | AE19: 28073.4
D20: 0.1 | E20: 48549.699 | G20: 0.1 | H20: 48549.699 | R20: ML Engineer | S20: 64748.409 | AA20: India | AB20: 28247.242 | AD20: India | AE20: 28247.242
D21: 0.11 | E21: 55955.641 | G21: 0.11 | H21: 55955.641 | AA21: Nepal | AB21: 28366.929 | AD21: Nepal | AE21: 28366.929
D22: 0.12 | E22: 57101.681 | G22: 0.12 | H22: 57101.681 | AA22: Philippines | AB22: 39303.959 | AD22: Philippines | AE22: 39303.959
D23: 0.13 | E23: 51175.601 | G23: 0.13 | H23: 51175.601 | AA23: Thailand | AB23: 41983.881 | AD23: Thailand | AE23: 41983.881
D24: 0.14 | E24: 53133.267 | G24: 0.14 | H24: 53133.267 | J24: Row Labels | K24: Average of ai_intensity_score | AA24: Malaysia | AB24: 42328.851 | AD24: Malaysia | AE24: 42328.851
D25: 0.15 | E25: 53743.026 | G25: 0.15 | H25: 53743.026 | J25: Healthcare | K25: 0.256 | AA25: Vietnam | AB25: 42337.711 | AD25: Vietnam | AE25: 42337.711
D26: 0.16 | E26: 55328.05 | G26: 0.16 | H26: 55328.05 | J26: Manufacturing | K26: 0.2578185 | AA26: Singapore | AB26: 43317.494 | AD26: Singapore | AE26: 43317.494
D27: 0.17 | E27: 53675.669 | G27: 0.17 | H27: 53675.669 | J27: Agriculture | K27: 0.25947276 | AA27: Indonesia | AB27: 43503.172 | AD27: Indonesia | AE27: 43503.172
D28: 0.18 | E28: 49278.89 | G28: 0.18 | H28: 49278.89 | J28: Government | K28: 0.26467033 | AA28: Peru | AB28: 46938.3 | AD28: Peru | AE28: 46938.3
D29: 0.19 | E29: 54504.739 | G29: 0.19 | H29: 54504.739 | J29: Education | K29: 0.26676636 | AA29: Brazil | AB29: 48475.361 | AD29: Brazil | AE29: 48475.361
D30: 0.2 | E30: 52503.558 | G30: 0.2 | H30: 52503.558 | J30: Energy | K30: 0.2752682 | AA30: Argentina | AB30: 49177.031 | AD30: Argentina | AE30: 49177.031
D31: 0.4 | E31: 75629.2 | G31: 0.4 | H31: 75629.2 | J31: Retail | K31: 0.27975309 | AA31: Colombia | AB31: 49586.511 | AD31: Colombia | AE31: 49586.511
D32: 0.41 | E32: 93897.31 | G32: 0.41 | H32: 93897.31 | J32: Tech | K32: 0.35841105 | AA32: Chile | AB32: 51133.908 | AD32: Chile | AE32: 51133.908
D33: 0.42 | E33: 85982.136 | G33: 0.42 | H33: 85982.136 | J33: Finance | K33: 0.36570128 | AA33: UAE | AB33: 68625.829 | AD33: UAE | AE33: 68625.829
D34: 0.43 | E34: 89679.974 | G34: 0.43 | H34: 89679.974 | AA34: Saudi Arabia | AB34: 68979.232 | AD34: Saudi Arabia | AE34: 68979.232
D35: 0.44 | E35: 72741.455 | G35: 0.44 | H35: 72741.455 | AA35: Qatar | AB35: 69704.356 | AD35: Qatar | AE35: 69704.356
D36: 0.45 | E36: 88111.744 | G36: 0.45 | H36: 88111.744 | AA36: Israel | AB36: 70108.104 | AD36: Israel | AE36: 70108.104
D37: 0.46 | E37: 86814.7 | G37: 0.46 | H37: 86814.7 | J37: Distinct Count of job_id | K37: Column Labels | AA37: Jordan | AB37: 71506.933 | AD37: Jordan | AE37: 71506.933
D38: 0.47 | E38: 85051.345 | G38: 0.47 | H38: 85051.345 | J38: Row Labels | K38: Emerging | L38: Growing | M38: Mature | AA38: South Korea | AB38: 75592.292 | AD38: South Korea | AE38: 75592.292
D39: 0.48 | E39: 81106.345 | G39: 0.48 | H39: 81106.345 | J39: Retail | K39: 238 | L39: 329 | AA39: Taiwan | AB39: 76108.541 | AD39: Taiwan | AE39: 76108.541
D40: 0.49 | E40: 92595.571 | G40: 0.49 | H40: 92595.571 | J40: Agriculture | K40: 245 | L40: 324 | AA40: China | AB40: 77384.847 | AD40: China | AE40: 77384.847
D41: 0.5 | E41: 90394.1 | G41: 0.5 | H41: 90394.1 | J41: Education | K41: 222 | L41: 313 | AA41: Japan | AB41: 78605.739 | AD41: Japan | AE41: 78605.739
D42: 0.51 | E42: 95100.3 | G42: 0.51 | H42: 95100.3 | J42: Energy | K42: 242 | L42: 280 | AA42: Sweden | AB42: 80408.026 | AD42: Sweden | AE42: 80408.026
D43: 0.52 | E43: 91731.583 | G43: 0.52 | H43: 91731.583 | J43: Finance | K43: 248 | L43: 167 | M43: 134 | AA43: United Kingdom | AB43: 80833.3 | AD43: United Kingdom | AE43: 80833.3
...

Sheet Charts
Q69: Average of ai_intensity_score | R69: Column Labels
Q70: Row Labels | R70: AI Researcher | S70: Business Analyst | T70: Data Scientist | U70: ML Engineer | V70: Operations Manager | W70: Policy Analyst | X70: Product Manager | Y70: Research Scientist | Z70: Software Engineer | AA70: Systems Engineer
Q71: Agriculture | R71: 0.24539683 | S71: 0.24277778 | T71: 0.26622642 | U71: 0.27138462 | V71: 0.33163636 | W71: 0.23777778 | X71: 0.25092593 | Y71: 0.25537037 | Z71: 0.20546875 | AA71: 0.28854839
Q72: Education | R72: 0.28191489 | S72: 0.2982 | T72: 0.24716667 | U72: 0.3030303 | V72: 0.22 | W72: 0.25375 | X72: 0.27470588 | Y72: 0.19941176 | Z72: 0.32698113 | AA72: 0.2558
Q73: Energy | R73: 0.35923077 | S73: 0.24684211 | T73: 0.23270833 | U73: 0.25903846 | V73: 0.34824561 | W73: 0.2286 | X73: 0.15575 | Y73: 0.28673077 | Z73: 0.27036364 | AA73: 0.32220339
Q74: Finance | R74: 0.42744681 | S74: 0.40978261 | T74: 0.32796296 | U74: 0.41904762 | V74: 0.38936508 | W74: 0.37596774 | X74: 0.33327273 | Y74: 0.36166667 | Z74: 0.26177778 | AA74: 0.33733333
Q75: Government | R75: 0.23264151 | S75: 0.24404255 | T75: 0.23615385 | U75: 0.29066667 | V75: 0.30432836 | W75: 0.27096154 | X75: 0.31973684 | Y75: 0.25873016 | Z75: 0.31609756 | AA75: 0.2005
Q76: Healthcare | R76: 0.30181818 | S76: 0.18117647 | T76: 0.24129032 | U76: 0.19196721 | V76: 0.27927273 | W76: 0.27714286 | X76: 0.3276087 | Y76: 0.23035088 | Z76: 0.23741379 | AA76: 0.30508475
Q77: Manufacturing | R77: 0.20016949 | S77: 0.26545455 | T77: 0.21849057 | U77: 0.23492063 | V77: 0.25153846 | W77: 0.26326531 | X77: 0.30545455 | Y77: 0.30153846 | Z77: 0.29274194 | AA77: 0.2477551
Q78: Retail | R78: 0.245 | S78: 0.27396825 | T78: 0.29976744 | U78: 0.31828125 | V78: 0.23807692 | W78: 0.26416667 | X78: 0.24302326 | Y78: 0.28875 | Z78: 0.37520833 | AA78: 0.25903846
Q79: Tech | R79: 0.34287879 | S79: 0.32913043 | T79: 0.40354167 | U79: 0.40390625 | V79: 0.3775 | W79: 0.31980769 | X79: 0.40172414 | Y79: 0.36538462 | Z79: 0.33939394 | AA79: 0.29259259

Sheet KPI's 
A1: Average of salary_usd | F1: Row Labels | G1: Distinct Count of job_id
A2: 63096.185 | B2: Average Salary | F2: Medium Risk | G2: 0.2224
F3: High Risk | G3: 0.4584
A4: Average of ai_job_displacement_risk_score | F4: Low Risk | G4: 0.3192 | H4: High AI Exposure Risk
A5: 0.586176 | B5: AI Displacement Risk Score
F7: Row Labels | G7: Distinct Count of job_id
F8: Low | G8: 0.6754
F9: Medium | G9: 0.149
F10: High | G10: 0.1756 | H10: High AI Dependency
F13: Row Labels | G13: Count of job_id
F14: 0 | G14: 0.6754
A15: Row Labels | B15: Average of salary_usd | F15: 1 | G15: 0.3246 | H15: AI Adoption rate
A16: 0
A17: 1 | B17: 0.57832637 | C17: AI Skills Salary Premium
A20: Row Labels | B20: Average of salary_usd
A21: 2010
A22: 2011 | B22: 0.00714474
A23: 2012 | B23: -0.0027952437 | F23: Row Labels | G23: Average of salary_usd | H23: Salary Growth | J23: Row Labels
A24: 2013 | B24: 0.06859971 | F24: 2010 | G24: 47536.159 | H24: 0 | J24: 2010 | K24: =_xlfn.XLOOKUP(J24, F24:F39, H24:H39) -> 0
A25: 2014 | B25: 0.13994748 | F25: 2011 | G25: 47875.793 | H25: =(G25/G24)-1 -> 0.00714474 | J25: 2011 | K25: =_xlfn.XLOOKUP(J25,F24:F39, H24:H39) -> 0.00714474
A26: 2015 | B26: 0.17161352 | F26: 2012 | G26: 47403.284 | H26: =(G26/G25)-1 -> -0.0098694689 | J26: 2012 | K26: =_xlfn.XLOOKUP(J26, F26:F41, H26:H41) -> -0.0098694689
A27: 2016 | B27: 0.17826846 | F27: 2013 | G27: 50797.126 | H27: =(G27/G26)-1 -> 0.07159508 | J27: 2013 | K27: =_xlfn.XLOOKUP(J27,F26:F41, H26:H41) -> 0.07159508
A28: 2017 | B28: 0.20279903 | F28: 2014 | G28: 54188.725 | H28: =(G28/G27)-1 -> 0.066767536 | J28: 2014 | K28: =_xlfn.XLOOKUP(J28, F28:F43, H28:H43) -> 0.066767536
A29: 2018 | B29: 0.37469238 | F29: 2015 | G29: 55694.006 | H29: =(G29/G28)-1 -> 0.027778504 | J29: 2015 | K29: =_xlfn.XLOOKUP(J29,F28:F43, H28:H43) -> 0.027778504
A30: 2019 | B30: 0.38416978 | F30: 2016 | G30: 56010.357 | H30: =(G30/G29)-1 -> 0.0056801535 | J30: 2016 | K30: =_xlfn.XLOOKUP(J30, F30:F45, H30:H45) -> 0.0056801535
A31: 2020 | B31: 0.45773657 | F31: 2017 | G31: 57176.446 | H31: =(G31/G30)-1 -> 0.020819167 | J31: 2017 | K31: =_xlfn.XLOOKUP(J31,F30:F45, H30:H45) -> 0.020819167
A32: 2021 | B32: 0.47998718 | F32: 2018 | G32: 65347.596 | H32: =(G32/G31)-1 -> 0.14291112 | J32: 2018 | K32: =_xlfn.XLOOKUP(J32, F32:F47, H32:H47) -> 0.14291112
A33: 2022 | B33: 0.61641351 | F33: 2019 | G33: 65798.115 | H33: =(G33/G32)-1 -> 0.0068941949 | J33: 2019 | K33: =_xlfn.XLOOKUP(J33,F32:F47, H32:H47) -> 0.0068941949
A34: 2023 | B34: 0.63641626 | F34: 2020 | G34: 69295.197 | H34: =(G34/G33)-1 -> 0.053148674 | J34: 2020 | K34: =_xlfn.XLOOKUP(J34, F34:F49, H34:H49) -> 0.053148674
A35: 2024 | B35: 0.740031 | F35: 2021 | G35: 70352.906 | H35: =(G35/G34)-1 -> 0.015263811 | J35: 2021 | K35: =_xlfn.XLOOKUP(J35,F34:F49, H34:H49) -> 0.015263811
A36: 2025 | B36: 0.7622417 | C36: Salary Growth (2010–2025) | F36: 2022 | G36: 76838.09 | H36: =(G36/G35)-1 -> 0.092180749 | J36: 2022 | K36: =_xlfn.XLOOKUP(J36, F36:F51, H36:H51) -> 0.092180749
F37: 2023 | G37: 77788.944 | H37: =(G37/G36)-1 -> 0.012374772 | J37: 2023 | K37: =_xlfn.XLOOKUP(J37,F36:F51, H36:H51) -> 0.012374772
F38: 2024 | G38: 82714.39 | H38: =(G38/G37)-1 -> 0.063318085 | J38: 2024 | K38: =_xlfn.XLOOKUP(J38, F38:F53, H38:H53) -> 0.063318085
F39: 2025 | G39: 83770.202 | H39: =(G39/G38)-1 -> 0.012764543 | J39: 2025 | K39: =_xlfn.XLOOKUP(J39,F38:F53, H38:H53) -> 0.012764543

Sheet Statistics
A1: DESCRIPTIVE STATISTICS — Key Numeric Metrics
A3: Salary (USD)
A4: Column: salary_usd | Annual salary in US dollars for each job posting.
A5: Statistic | B5: Value | C5: Benefit of This Metric
A6: Count | B6: =COUNT('Raw Data '!O:O) -> 5000 | C6: Confirms dataset completeness; identifies if any records are missing.
A7: Sum | B7: =SUM('Raw Data '!O:O) -> 315480924 | C7: Total aggregate value; useful for budget/payroll sizing.
A8: Average (Mean) | B8: =AVERAGE('Raw Data '!O:O) -> 63096.185 | C8: Central tendency benchmark for comparisons across groups.
A9: Median (P50) | B9: =MEDIAN('Raw Data '!O:O) -> 60909.5 | C9: Robust central value unaffected by extreme salaries/outliers. | G9: • Average salary: $63,096 | Median salary: $60,910 — a modest right skew driven by senior/tech roles.
A10: Min | B10: =MIN('Raw Data '!O:O) -> 15321 | C10: Identifies the floor value; helps detect potential data errors.
A11: Max | B11: =MAX('Raw Data '!O:O) -> 161547 | C11: Identifies the ceiling; flags outliers and exceptional cases.
A12: Std Dev | B12: =_xlfn.STDEV.S('Raw Data '!O:O) -> 31431.272 | C12: Dispersion measure — high std dev signals wide salary inequality.
A13: 25th Percentile | B13: 36575.5 | C13: Lower quartile boundary for low-range roles.
A14: 75th Percentile | B14: 81811.75 | C14: Upper quartile boundary for high-range roles.
A15: IQR (75th - 25th) | B15: 45236.25 | C15: Middle 50% spread — narrower = more uniform distribution.
A18: AI Intensity Score
A19: Column: ai_intensity_score | 0–1 score reflecting how AI-centric the job role is.
A20: Statistic | B20: Value | C20: Benefit of This Metric
A21: Count | B21: 5000 | C21: Confirms dataset completeness; identifies if any records are missing.
A22: Sum | B22: 1436.56 | C22: Total aggregate value; useful for budget/payroll sizing.
A23: Average (Mean) | B23: 0.29 | C23: Central tendency benchmark for comparisons across groups.
A24: Median (P50) | B24: 0.15 | C24: Robust central value unaffected by extreme salaries/outliers.
A25: Min | B25: 0 | C25: Identifies the floor value; helps detect potential data errors.
A26: Max | B26: 0.95 | C26: Identifies the ceiling; flags outliers and exceptional cases.
A27: Std Dev | B27: 0.29 | C27: Dispersion measure — high std dev signals wide salary inequality.
A28: 25th Percentile | B28: 0.07 | C28: Lower quartile boundary for low-range roles.
A29: 75th Percentile | B29: 0.52 | C29: Upper quartile boundary for high-range roles.
A30: IQR (75th - 25th) | B30: 0.45 | C30: Middle 50% spread — narrower = more uniform distribution.
A33: AI Job Displacement Risk Score
A34: Column: aI_job_displacement_risk_score | 0–1 probability that the role is automatable.
A35: Statistic | B35: Value | C35: Benefit of This Metric
A36: Count | B36: 5000 | C36: Confirms dataset completeness; identifies if any records are missing.
A37: Sum | B37: 2930.88 | C37: Total aggregate value; useful for budget/payroll sizing.
A38: Average (Mean) | B38: 0.59 | C38: Central tendency benchmark for comparisons across groups.
A39: Median (P50) | B39: 0.67 | C39: Robust central value unaffected by extreme salaries/outliers.
A40: Min | B40: 0.1 | C40: Identifies the floor value; helps detect potential data errors.
A41: Max | B41: 0.9 | C41: Identifies the ceiling; flags outliers and exceptional cases.
A42: Std Dev | B42: 0.25 | C42: Dispersion measure — high std dev signals wide salary inequality.
A43: 25th Percentile | B43: 0.33 | C43: Lower quartile boundary for low-range roles.
A44: 75th Percentile | B44: 0.79 | C44: Upper quartile boundary for high-range roles.
A45: IQR (75th - 25th) | B45: 0.46 | C45: Middle 50% spread — narrower = more uniform distribution.
...

Sheet Dashboard 
D1: AI & Job Automation(2010-2025)

Sheet Dashboard (2)
D1: AI & Job Automation(2010-2025)

Sheet Dashboard (3)
D1: AI & Job Automation(2010-2025)
